Workbook

Sheet 00_README
B1: USDINR FX RESEARCH LAB — STEP 2: EXPLORATORY HISTORICAL ANALYSIS
B2: Workbook 02 | Exploratory only — NO strategy, NO directional view, NO assumed IV-RV predictiveness
B4: SCOPE
B5: Sample | C5: 2013-01-01 to 2026-09-09 (3,306 daily obs, Indian business days)
B6: Instrument | C6: USDINR spot (Bloomberg INR REGN Curncy) + USDINR 3M ATM implied vol
B7: Prepared | C7: 2026-09-17 | All calculations reproducible from RAW sheets via live formulas
B9: DATA SEPARATION (do not mix)
B10: 01_RAW_* | C10: Source data, UNTOUCHED. Never edit. Sorted ascending by date.
B11: 02_MASTER | C11: All derived series as live formulas referencing RAW. The single calculation engine.
B12: 03-07 | C12: Research outputs (stats, regimes, IV-RV, events, patterns) referencing MASTER.
B13: 08_CHARTS | C13: Visual research output.
B15: CRITICAL: LOOK-AHEAD DISCIPLINE
B16: Trailing RV (tRV) | C16: Computed from PAST spot returns only (21d / 63d windows). KNOWN at date t. Use as feature.
B17: Forward RV / Fwd Spot | C17: Realized over t -> t+1M / t+3M. NOT known at t. OUTCOME ONLY (peach columns). Never a feature.
B18: Original file RV | C18: The RV in the source file was FORWARD 3M vol. Carried here as Fwd_RV_3M (outcome), not as a feature.
B19: PIT percentiles | C19: IV / RV percentiles use EXPANDING windows (252d burn-in) so only past data informs each date.
B20: Regime bands | C20: Full-sample percentile bands = DESCRIPTIVE map only. For backtesting, re-derive with expanding windows.
B22: RESEARCH DISCIPLINE (terminology)
B23: OBSERVATION | C23: What the data shows.
B24: PATTERN | C24: A recurring statistical relationship, precisely defined.
B25: HYPOTHESIS | C25: A possible explanation (not yet tested).
B26: CAUSALITY | C26: NOT claimed anywhere in this workbook. Requires independent establishment.
B28: KEY CAVEATS
B29: Overlapping windows | C29: Forward 1M/3M outcomes overlap heavily -> reported t-stats are INDICATIVE, overstate significance.
B30: Single tenor | C30: Only 3M ATM IV available. No term structure, no skew (risk reversals), no forwards.
B31: Persistence | C31: Vol is highly persistent (near unit-root). Much apparent "prediction" is regime persistence, not skill.

Sheet 01_RAW_Spot
A1: Date | B1: PX_LAST (INR/USD)
A2: 41275 | B2: 54.685
A3: 41276 | B3: 54.36
A4: 41277 | B4: 54.49
A5: 41278 | B5: 55.075
A6: 41281 | B6: 55.225
A7: 41282 | B7: 55.005
A8: 41283 | B8: 54.755
A9: 41284 | B9: 54.575
A10: 41285 | B10: 54.76
A11: 41288 | B11: 54.4975
A12: 41289 | B12: 54.625
A13: 41290 | B13: 54.695
... A3307: 46274 | B3307: 95.0975

Sheet 01_RAW_IV
A1: Date | B1: IV_3M_ATM (frac)
A2: 41275 | B2: 0.101075
A3: 41276 | B3: 0.101225
A4: 41277 | B4: 0.100275
A5: 41278 | B5: 0.1
A6: 41281 | B6: 0.099025
A7: 41282 | B7: 0.098575
A8: 41283 | B8: 0.097975
A9: 41284 | B9: 0.099075
A10: 41285 | B10: 0.098425
A11: 41288 | B11: 0.098675
A12: 41289 | B12: 0.098225
A13: 41290 | B13: 0.098
... A3307: 46274 | B3307: 0.042925

Sheet 01_RAW_FwdRV
A1: Date | B1: Fwd3M_RV_ORIG (frac)
A2: 41275 | B2: 0.071567896
A3: 41276 | B3: 0.070510072
A4: 41277 | B4: 0.070645552
A5: 41278 | B5: 0.069155385
A6: 41281 | B6: 0.068954021
A7: 41282 | B7: 0.069043174
A8: 41283 | B8: 0.068416131
A9: 41284 | B9: 0.068114346
A10: 41285 | B10: 0.068329954
A11: 41288 | B11: 0.067589144
A12: 41289 | B12: 0.067528738
A13: 41290 | B13: 0.069962806
... A3243: 46182 | B3243: 0.042687567
A3244: 46183
A3245: 46184
A3246: 46185
A3247: 46188
A3248: 46189
A3249: 46190
A3250: 46191
A3251: 46192
A3252: 46195
A3253: 46196
A3254: 46197
A3255: 46198
... A3307: 46274

Sheet 02_MASTER
A1: Date | B1: Spot | C1: IV_3M_ATM | D1: LogRet | E1: tRV_1M | F1: tRV_3M | G1: IV_minus_tRV3M | H1: IV_over_tRV3M | I1: Fwd_RV_3M[OUT] | J1: Fwd_RV_1M[OUT] | K1: Fwd_Spot_3M[OUT] | L1: IV_pct_PIT | M1: RV3M_pct_PIT | N1: IVmRV_z_PIT | O1: Regime | P1: Regime_next | Q1: Year
A2: 41275 | B2: ='01_RAW_Spot'!B2 | C2: ='01_RAW_IV'!B2 | G2: =IF(OR(C2="",F2=""),"",C2-F2) | H2: =IF(OR(C2="",F2="",F2=0),"",C2/F2) | I2: =IF('01_RAW_FwdRV'!B2="","",'01_RAW_FwdRV'!B2) | J2: =IF(ROW()<=3286,STDEV(D3:D23)*SQRT(252),"") | K2: =IF(ROW()<=3244,LN(B65/B2),"") | O2: =IF(F2="","",IF(F2<'04_VOLATILITY_REGIMES'!$C$5,"Low",IF(F2<'04_VOLATILITY_REGIMES'!$C$6,"Normal",IF(F2<'04_VOLATILITY_REGIMES'!$C$7,"High","Extreme")))) | P2: =O3 | Q2: =YEAR(A2)
A3: 41276 | B3: ='01_RAW_Spot'!B3 | C3: ='01_RAW_IV'!B3 | D3: =LN(B3/B2) | G3: =IF(OR(C3="",F3=""),"",C3-F3) | H3: =IF(OR(C3="",F3="",F3=0),"",C3/F3) | I3: =IF('01_RAW_FwdRV'!B3="","",'01_RAW_FwdRV'!B3) | J3: =IF(ROW()<=3286,STDEV(D4:D24)*SQRT(252),"") | K3: =IF(ROW()<=3244,LN(B66/B3),"") | O3: =IF(F3="","",IF(F3<'04_VOLATILITY_REGIMES'!$C$5,"Low",IF(F3<'04_VOLATILITY_REGIMES'!$C$6,"Normal",IF(F3<'04_VOLATILITY_REGIMES'!$C$7,"High","Extreme")))) | P3: =O4 | Q3: =YEAR(A3)
A4: 41277 | B4: ='01_RAW_Spot'!B4 | C4: ='01_RAW_IV'!B4 | D4: =LN(B4/B3) | G4: =IF(OR(C4="",F4=""),"",C4-F4) | H4: =IF(OR(C4="",F4="",F4=0),"",C4/F4) | I4: =IF('01_RAW_FwdRV'!B4="","",'01_RAW_FwdRV'!B4) | J4: =IF(ROW()<=3286,STDEV(D5:D25)*SQRT(252),"") | K4: =IF(ROW()<=3244,LN(B67/B4),"") | O4: =IF(F4="","",IF(F4<'04_VOLATILITY_REGIMES'!$C$5,"Low",IF(F4<'04_VOLATILITY_REGIMES'!$C$6,"Normal",IF(F4<'04_VOLATILITY_REGIMES'!$C$7,"High","Extreme")))) | P4: =O5 | Q4: =YEAR(A4)
A5: 41278 | B5: ='01_RAW_Spot'!B5 | C5: ='01_RAW_IV'!B5 | D5: =LN(B5/B4) | G5: =IF(OR(C5="",F5=""),"",C5-F5) | H5: =IF(OR(C5="",F5="",F5=0),"",C5/F5) | I5: =IF('01_RAW_FwdRV'!B5="","",'01_RAW_FwdRV'!B5) | J5: =IF(ROW()<=3286,STDEV(D6:D26)*SQRT(252),"") | K5: =IF(ROW()<=3244,LN(B68/B5),"") | O5: =IF(F5="","",IF(F5<'04_VOLATILITY_REGIMES'!$C$5,"Low",IF(F5<'04_VOLATILITY_REGIMES'!$C$6,"Normal",IF(F5<'04_VOLATILITY_REGIMES'!$C$7,"High","Extreme")))) | P5: =O6 | Q5: =YEAR(A5)
A6: 41281 | B6: ='01_RAW_Spot'!B6 | C6: ='01_RAW_IV'!B6 | D6: =LN(B6/B5) | G6: =IF(OR(C6="",F6=""),"",C6-F6) | H6: =IF(OR(C6="",F6="",F6=0),"",C6/F6) | I6: =IF('01_RAW_FwdRV'!B6="","",'01_RAW_FwdRV'!B6) | J6: =IF(ROW()<=3286,STDEV(D7:D27)*SQRT(252),"") | K6: =IF(ROW()<=3244,LN(B69/B6),"") | O6: =IF(F6="","",IF(F6<'04_VOLATILITY_REGIMES'!$C$5,"Low",IF(F6<'04_VOLATILITY_REGIMES'!$C$6,"Normal",IF(F6<'04_VOLATILITY_REGIMES'!$C$7,"High","Extreme")))) | P6: =O7 | Q6: =YEAR(A6)
A7: 41282 | B7: ='01_RAW_Spot'!B7 | C7: ='01_RAW_IV'!B7 | D7: =LN(B7/B6) | G7: =IF(OR(C7="",F7=""),"",C7-F7) | H7: =IF(OR(C7="",F7="",F7=0),"",C7/F7) | I7: =IF('01_RAW_FwdRV'!B7="","",'01_RAW_FwdRV'!B7) | J7: =IF(ROW()<=3286,STDEV(D8:D28)*SQRT(252),"") | K7: =IF(ROW()<=3244,LN(B70/B7),"") | O7: =IF(F7="","",IF(F7<'04_VOLATILITY_REGIMES'!$C$5,"Low",IF(F7<'04_VOLATILITY_REGIMES'!$C$6,"Normal",IF(F7<'04_VOLATILITY_REGIMES'!$C$7,"High","Extreme")))) | P7: =O8 | Q7: =YEAR(A7)
A8: 41283 | B8: ='01_RAW_Spot'!B8 | C8: ='01_RAW_IV'!B8 | D8: =LN(B8/B7) | G8: =IF(OR(C8="",F8=""),"",C8-F8) | H8: =IF(OR(C8="",F8="",F8=0),"",C8/F8) | I8: =IF('01_RAW_FwdRV'!B8="","",'01_RAW_FwdRV'!B8) | J8: =IF(ROW()<=3286,STDEV(D9:D29)*SQRT(252),"") | K8: =IF(ROW()<=3244,LN(B71/B8),"") | O8: =IF(F8="","",IF(F8<'04_VOLATILITY_REGIMES'!$C$5,"Low",IF(F8<'04_VOLATILITY_REGIMES'!$C$6,"Normal",IF(F8<'04_VOLATILITY_REGIMES'!$C$7,"High","Extreme")))) | P8: =O9 | Q8: =YEAR(A8)
A9: 41284 | B9: ='01_RAW_Spot'!B9 | C9: ='01_RAW_IV'!B9 | D9: =LN(B9/B8) | G9: =IF(OR(C9="",F9=""),"",C9-F9) | H9: =IF(OR(C9="",F9="",F9=0),"",C9/F9) | I9: =IF('01_RAW_FwdRV'!B9="","",'01_RAW_FwdRV'!B9) | J9: =IF(ROW()<=3286,STDEV(D10:D30)*SQRT(252),"") | K9: =IF(ROW()<=3244,LN(B72/B9),"") | O9: =IF(F9="","",IF(F9<'04_VOLATILITY_REGIMES'!$C$5,"Low",IF(F9<'04_VOLATILITY_REGIMES'!$C$6,"Normal",IF(F9<'04_VOLATILITY_REGIMES'!$C$7,"High","Extreme")))) | P9: =O10 | Q9: =YEAR(A9)
A10: 41285 | B10: ='01_RAW_Spot'!B10 | C10: ='01_RAW_IV'!B10 | D10: =LN(B10/B9) | G10: =IF(OR(C10="",F10=""),"",C10-F10) | H10: =IF(OR(C10="",F10="",F10=0),"",C10/F10) | I10: =IF('01_RAW_FwdRV'!B10="","",'01_RAW_FwdRV'!B10) | J10: =IF(ROW()<=3286,STDEV(D11:D31)*SQRT(252),"") | K10: =IF(ROW()<=3244,LN(B73/B10),"") | O10: =IF(F10="","",IF(F10<'04_VOLATILITY_REGIMES'!$C$5,"Low",IF(F10<'04_VOLATILITY_REGIMES'!$C$6,"Normal",IF(F10<'04_VOLATILITY_REGIMES'!$C$7,"High","Extreme")))) | P10: =O11 | Q10: =YEAR(A10)
A11: 41288 | B11: ='01_RAW_Spot'!B11 | C11: ='01_RAW_IV'!B11 | D11: =LN(B11/B10) | G11: =IF(OR(C11="",F11=""),"",C11-F11) | H11: =IF(OR(C11="",F11="",F11=0),"",C11/F11) | I11: =IF('01_RAW_FwdRV'!B11="","",'01_RAW_FwdRV'!B11) | J11: =IF(ROW()<=3286,STDEV(D12:D32)*SQRT(252),"") | K11: =IF(ROW()<=3244,LN(B74/B11),"") | O11: =IF(F11="","",IF(F11<'04_VOLATILITY_REGIMES'!$C$5,"Low",IF(F11<'04_VOLATILITY_REGIMES'!$C$6,"Normal",IF(F11<'04_VOLATILITY_REGIMES'!$C$7,"High","Extreme")))) | P11: =O12 | Q11: =YEAR(A11)
A12: 41289 | B12: ='01_RAW_Spot'!B12 | C12: ='01_RAW_IV'!B12 | D12: =LN(B12/B11) | G12: =IF(OR(C12="",F12=""),"",C12-F12) | H12: =IF(OR(C12="",F12="",F12=0),"",C12/F12) | I12: =IF('01_RAW_FwdRV'!B12="","",'01_RAW_FwdRV'!B12) | J12: =IF(ROW()<=3286,STDEV(D13:D33)*SQRT(252),"") | K12: =IF(ROW()<=3244,LN(B75/B12),"") | O12: =IF(F12="","",IF(F12<'04_VOLATILITY_REGIMES'!$C$5,"Low",IF(F12<'04_VOLATILITY_REGIMES'!$C$6,"Normal",IF(F12<'04_VOLATILITY_REGIMES'!$C$7,"High","Extreme")))) | P12: =O13 | Q12: =YEAR(A12)
A13: 41290 | B13: ='01_RAW_Spot'!B13 | C13: ='01_RAW_IV'!B13 | D13: =LN(B13/B12) | G13: =IF(OR(C13="",F13=""),"",C13-F13) | H13: =IF(OR(C13="",F13="",F13=0),"",C13/F13) | I13: =IF('01_RAW_FwdRV'!B13="","",'01_RAW_FwdRV'!B13) | J13: =IF(ROW()<=3286,STDEV(D14:D34)*SQRT(252),"") | K13: =IF(ROW()<=3244,LN(B76/B13),"") | O13: =IF(F13="","",IF(F13<'04_VOLATILITY_REGIMES'!$C$5,"Low",IF(F13<'04_VOLATILITY_REGIMES'!$C$6,"Normal",IF(F13<'04_VOLATILITY_REGIMES'!$C$7,"High","Extreme")))) | P13: =O14 | Q13: =YEAR(A13)
A14: 41291 | B14: ='01_RAW_Spot'!B14 | C14: ='01_RAW_IV'!B14 | D14: =LN(B14/B13) | G14: =IF(OR(C14="",F14=""),"",C14-F14) | H14: =IF(OR(C14="",F14="",F14=0),"",C14/F14) | I14: =IF('01_RAW_FwdRV'!B14="","",'01_RAW_FwdRV'!B14) | J14: =IF(ROW()<=3286,STDEV(D15:D35)*SQRT(252),"") | K14: =IF(ROW()<=3244,LN(B77/B14),"") | O14: =IF(F14="","",IF(F14<'04_VOLATILITY_REGIMES'!$C$5,"Low",IF(F14<'04_VOLATILITY_REGIMES'!$C$6,"Normal",IF(F14<'04_VOLATILITY_REGIMES'!$C$7,"High","Extreme")))) | P14: =O15 | Q14: =YEAR(A14)
... A22: 41304 | B22: ='01_RAW_Spot'!B22 | C22: ='01_RAW_IV'!B22 | D22: =LN(B22/B21) | G22: =IF(OR(C22="",F22=""),"",C22-F22) | H22: =IF(OR(C22="",F22="",F22=0),"",C22/F22) | I22: =IF('01_RAW_FwdRV'!B22="","",'01_RAW_FwdRV'!B22) | J22: =IF(ROW()<=3286,STDEV(D23:D43)*SQRT(252),"") | K22: =IF(ROW()<=3244,LN(B85/B22),"") | O22: =IF(F22="","",IF(F22<'04_VOLATILITY_REGIMES'!$C$5,"Low",IF(F22<'04_VOLATILITY_REGIMES'!$C$6,"Normal",IF(F22<'04_VOLATILITY_REGIMES'!$C$7,"High","Extreme")))) | P22: =O23 | Q22: =YEAR(A22)
A23: 41305 | B23: ='01_RAW_Spot'!B23 | C23: ='01_RAW_IV'!B23 | D23: =LN(B23/B22) | E23: =STDEV(D3:D23)*SQRT(252) | G23: =IF(OR(C23="",F23=""),"",C23-F23) | H23: =IF(OR(C23="",F23="",F23=0),"",C23/F23) | I23: =IF('01_RAW_FwdRV'!B23="","",'01_RAW_FwdRV'!B23) | J23: =IF(ROW()<=3286,STDEV(D24:D44)*SQRT(252),"") | K23: =IF(ROW()<=3244,LN(B86/B23),"") | O23: =IF(F23="","",IF(F23<'04_VOLATILITY_REGIMES'!$C$5,"Low",IF(F23<'04_VOLATILITY_REGIMES'!$C$6,"Normal",IF(F23<'04_VOLATILITY_REGIMES'!$C$7,"High","Extreme")))) | P23: =O24 | Q23: =YEAR(A23)
A24: 41306 | B24: ='01_RAW_Spot'!B24 | C24: ='01_RAW_IV'!B24 | D24: =LN(B24/B23) | E24: =STDEV(D4:D24)*SQRT(252) | G24: =IF(OR(C24="",F24=""),"",C24-F24) | H24: =IF(OR(C24="",F24="",F24=0),"",C24/F24) | I24: =IF('01_RAW_FwdRV'!B24="","",'01_RAW_FwdRV'!B24) | J24: =IF(ROW()<=3286,STDEV(D25:D45)*SQRT(252),"") | K24: =IF(ROW()<=3244,LN(B87/B24),"") | O24: =IF(F24="","",IF(F24<'04_VOLATILITY_REGIMES'!$C$5,"Low",IF(F24<'04_VOLATILITY_REGIMES'!$C$6,"Normal",IF(F24<'04_VOLATILITY_REGIMES'!$C$7,"High","Extreme")))) | P24: =O25 | Q24: =YEAR(A24)
A25: 41309 | B25: ='01_RAW_Spot'!B25 | C25: ='01_RAW_IV'!B25 | D25: =LN(B25/B24) | E25: =STDEV(D5:D25)*SQRT(252) | G25: =IF(OR(C25="",F25=""),"",C25-F25) | H25: =IF(OR(C25="",F25="",F25=0),"",C25/F25) | I25: =IF('01_RAW_FwdRV'!B25="","",'01_RAW_FwdRV'!B25) | J25: =IF(ROW()<=3286,STDEV(D26:D46)*SQRT(252),"") | K25: =IF(ROW()<=3244,LN(B88/B25),"") | O25: =IF(F25="","",IF(F25<'04_VOLATILITY_REGIMES'!$C$5,"Low",IF(F25<'04_VOLATILITY_REGIMES'!$C$6,"Normal",IF(F25<'04_VOLATILITY_REGIMES'!$C$7,"High","Extreme")))) | P25: =O26 | Q25: =YEAR(A25)
A26: 41310 | B26: ='01_RAW_Spot'!B26 | C26: ='01_RAW_IV'!B26 | D26: =LN(B26/B25) | E26: =STDEV(D6:D26)*SQRT(252) | G26: =IF(OR(C26="",F26=""),"",C26-F26) | H26: =IF(OR(C26="",F26="",F26=0),"",C26/F26) | I26: =IF('01_RAW_FwdRV'!B26="","",'01_RAW_FwdRV'!B26) | J26: =IF(ROW()<=3286,STDEV(D27:D47)*SQRT(252),"") | K26: =IF(ROW()<=3244,LN(B89/B26),"") | O26: =IF(F26="","",IF(F26<'04_VOLATILITY_REGIMES'!$C$5,"Low",IF(F26<'04_VOLATILITY_REGIMES'!$C$6,"Normal",IF(F26<'04_VOLATILITY_REGIMES'!$C$7,"High","Extreme")))) | P26: =O27 | Q26: =YEAR(A26)
A27: 41311 | B27: ='01_RAW_Spot'!B27 | C27: ='01_RAW_IV'!B27 | D27: =LN(B27/B26) | E27: =STDEV(D7:D27)*SQRT(252) | G27: =IF(OR(C27="",F27=""),"",C27-F27) | H27: =IF(OR(C27="",F27="",F27=0),"",C27/F27) | I27: =IF('01_RAW_FwdRV'!B27="","",'01_RAW_FwdRV'!B27) | J27: =IF(ROW()<=3286,STDEV(D28:D48)*SQRT(252),"") | K27: =IF(ROW()<=3244,LN(B90/B27),"") | O27: =IF(F27="","",IF(F27<'04_VOLATILITY_REGIMES'!$C$5,"Low",IF(F27<'04_VOLATILITY_REGIMES'!$C$6,"Normal",IF(F27<'04_VOLATILITY_REGIMES'!$C$7,"High","Extreme")))) | P27: =O28 | Q27: =YEAR(A27)
A28: 41312 | B28: ='01_RAW_Spot'!B28 | C28: ='01_RAW_IV'!B28 | D28: =LN(B28/B27) | E28: =STDEV(D8:D28)*SQRT(252) | G28: =IF(OR(C28="",F28=""),"",C28-F28) | H28: =IF(OR(C28="",F28="",F28=0),"",C28/F28) | I28: =IF('01_RAW_FwdRV'!B28="","",'01_RAW_FwdRV'!B28) | J28: =IF(ROW()<=3286,STDEV(D29:D49)*SQRT(252),"") | K28: =IF(ROW()<=3244,LN(B91/B28),"") | O28: =IF(F28="","",IF(F28<'04_VOLATILITY_REGIMES'!$C$5,"Low",IF(F28<'04_VOLATILITY_REGIMES'!$C$6,"Normal",IF(F28<'04_VOLATILITY_REGIMES'!$C$7,"High","Extreme")))) | P28: =O29 | Q28: =YEAR(A28)
A29: 41313 | B29: ='01_RAW_Spot'!B29 | C29: ='01_RAW_IV'!B29 | D29: =LN(B29/B28) | E29: =STDEV(D9:D29)*SQRT(252) | G29: =IF(OR(C29="",F29=""),"",C29-F29) | H29: =IF(OR(C29="",F29="",F29=0),"",C29/F29) | I29: =IF('01_RAW_FwdRV'!B29="","",'01_RAW_FwdRV'!B29) | J29: =IF(ROW()<=3286,STDEV(D30:D50)*SQRT(252),"") | K29: =IF(ROW()<=3244,LN(B92/B29),"") | O29: =IF(F29="","",IF(F29<'04_VOLATILITY_REGIMES'!$C$5,"Low",IF(F29<'04_VOLATILITY_REGIMES'!$C$6,"Normal",IF(F29<'04_VOLATILITY_REGIMES'!$C$7,"High","Extreme")))) | P29: =O30 | Q29: =YEAR(A29)
A30: 41316 | B30: ='01_RAW_Spot'!B30 | C30: ='01_RAW_IV'!B30 | D30: =LN(B30/B29) | E30: =STDEV(D10:D30)*SQRT(252) | G30: =IF(OR(C30="",F30=""),"",C30-F30) | H30: =IF(OR(C30="",F30="",F30=0),"",C30/F30) | I30: =IF('01_RAW_FwdRV'!B30="","",'01_RAW_FwdRV'!B30) | J30: =IF(ROW()<=3286,STDEV(D31:D51)*SQRT(252),"") | K30: =IF(ROW()<=3244,LN(B93/B30),"") | O30: =IF(F30="","",IF(F30<'04_VOLATILITY_REGIMES'!$C$5,"Low",IF(F30<'04_VOLATILITY_REGIMES'!$C$6,"Normal",IF(F30<'04_VOLATILITY_REGIMES'!$C$7,"High","Extreme")))) | P30: =O31 | Q30: =YEAR(A30)
A31: 41317 | B31: ='01_RAW_Spot'!B31 | C31: ='01_RAW_IV'!B31 | D31: =LN(B31/B30) | E31: =STDEV(D11:D31)*SQRT(252) | G31: =IF(OR(C31="",F31=""),"",C31-F31) | H31: =IF(OR(C31="",F31="",F31=0),"",C31/F31) | I31: =IF('01_RAW_FwdRV'!B31="","",'01_RAW_FwdRV'!B31) | J31: =IF(ROW()<=3286,STDEV(D32:D52)*SQRT(252),"") | K31: =IF(ROW()<=3244,LN(B94/B31),"") | O31: =IF(F31="","",IF(F31<'04_VOLATILITY_REGIMES'!$C$5,"Low",IF(F31<'04_VOLATILITY_REGIMES'!$C$6,"Normal",IF(F31<'04_VOLATILITY_REGIMES'!$C$7,"High","Extreme")))) | P31: =O32 | Q31: =YEAR(A31)
A32: 41318 | B32: ='01_RAW_Spot'!B32 | C32: ='01_RAW_IV'!B32 | D32: =LN(B32/B31) | E32: =STDEV(D12:D32)*SQRT(252) | G32: =IF(OR(C32="",F32=""),"",C32-F32) | H32: =IF(OR(C32="",F32="",F32=0),"",C32/F32) | I32: =IF('01_RAW_FwdRV'!B32="","",'01_RAW_FwdRV'!B32) | J32: =IF(ROW()<=3286,STDEV(D33:D53)*SQRT(252),"") | K32: =IF(ROW()<=3244,LN(B95/B32),"") | O32: =IF(F32="","",IF(F32<'04_VOLATILITY_REGIMES'!$C$5,"Low",IF(F32<'04_VOLATILITY_REGIMES'!$C$6,"Normal",IF(F32<'04_VOLATILITY_REGIMES'!$C$7,"High","Extreme")))) | P32: =O33 | Q32: =YEAR(A32)
A33: 41319 | B33: ='01_RAW_Spot'!B33 | C33: ='01_RAW_IV'!B33 | D33: =LN(B33/B32) | E33: =STDEV(D13:D33)*SQRT(252) | G33: =IF(OR(C33="",F33=""),"",C33-F33) | H33: =IF(OR(C33="",F33="",F33=0),"",C33/F33) | I33: =IF('01_RAW_FwdRV'!B33="","",'01_RAW_FwdRV'!B33) | J33: =IF(ROW()<=3286,STDEV(D34:D54)*SQRT(252),"") | K33: =IF(ROW()<=3244,LN(B96/B33),"") | O33: =IF(F33="","",IF(F33<'04_VOLATILITY_REGIMES'!$C$5,"Low",IF(F33<'04_VOLATILITY_REGIMES'!$C$6,"Normal",IF(F33<'04_VOLATILITY_REGIMES'!$C$7,"High","Extreme")))) | P33: =O34 | Q33: =YEAR(A33)
A34: 41320 | B34: ='01_RAW_Spot'!B34 | C34: ='01_RAW_IV'!B34 | D34: =LN(B34/B33) | E34: =STDEV(D14:D34)*SQRT(252) | G34: =IF(OR(C34="",F34=""),"",C34-F34) | H34: =IF(OR(C34="",F34="",F34=0),"",C34/F34) | I34: =IF('01_RAW_FwdRV'!B34="","",'01_RAW_FwdRV'!B34) | J34: =IF(ROW()<=3286,STDEV(D35:D55)*SQRT(252),"") | K34: =IF(ROW()<=3244,LN(B97/B34),"") | O34: =IF(F34="","",IF(F34<'04_VOLATILITY_REGIMES'!$C$5,"Low",IF(F34<'04_VOLATILITY_REGIMES'!$C$6,"Normal",IF(F34<'04_VOLATILITY_REGIMES'!$C$7,"High","Extreme")))) | P34: =O35 | Q34: =YEAR(A34)
... A64: 41368 | B64: ='01_RAW_Spot'!B64 | C64: ='01_RAW_IV'!B64 | D64: =LN(B64/B63) | E64: =STDEV(D44:D64)*SQRT(252) | G64: =IF(OR(C64="",F64=""),"",C64-F64) | H64: =IF(OR(C64="",F64="",F64=0),"",C64/F64) | I64: =IF('01_RAW_FwdRV'!B64="","",'01_RAW_FwdRV'!B64) | J64: =IF(ROW()<=3286,STDEV(D65:D85)*SQRT(252),"") | K64: =IF(ROW()<=3244,LN(B127/B64),"") | O64: =IF(F64="","",IF(F64<'04_VOLATILITY_REGIMES'!$C$5,"Low",IF(F64<'04_VOLATILITY_REGIMES'!$C$6,"Normal",IF(F64<'04_VOLATILITY_REGIMES'!$C$7,"High","Extreme")))) | P64: =O65 | Q64: =YEAR(A64)
A65: 41369 | B65: ='01_RAW_Spot'!B65 | C65: ='01_RAW_IV'!B65 | D65: =LN(B65/B64) | E65: =STDEV(D45:D65)*SQRT(252) | F65: =STDEV(D3:D65)*SQRT(252) | G65: =IF(OR(C65="",F65=""),"",C65-F65) | H65: =IF(OR(C65="",F65="",F65=0),"",C65/F65) | I65: =IF('01_RAW_FwdRV'!B65="","",'01_RAW_FwdRV'!B65) | J65: =IF(ROW()<=3286,STDEV(D66:D86)*SQRT(252),"") | K65: =IF(ROW()<=3244,LN(B128/B65),"") | O65: =IF(F65="","",IF(F65<'04_VOLATILITY_REGIMES'!$C$5,"Low",IF(F65<'04_VOLATILITY_REGIMES'!$C$6,"Normal",IF(F65<'04_VOLATILITY_REGIMES'!$C$7,"High","Extreme")))) | P65: =O66 | Q65: =YEAR(A65)
A66: 41372 | B66: ='01_RAW_Spot'!B66 | C66: ='01_RAW_IV'!B66 | D66: =LN(B66/B65) | E66: =STDEV(D46:D66)*SQRT(252) | F66: =STDEV(D4:D66)*SQRT(252) | G66: =IF(OR(C66="",F66=""),"",C66-F66) | H66: =IF(OR(C66="",F66="",F66=0),"",C66/F66) | I66: =IF('01_RAW_FwdRV'!B66="","",'01_RAW_FwdRV'!B66) | J66: =IF(ROW()<=3286,STDEV(D67:D87)*SQRT(252),"") | K66: =IF(ROW()<=3244,LN(B129/B66),"") | O66: =IF(F66="","",IF(F66<'04_VOLATILITY_REGIMES'!$C$5,"Low",IF(F66<'04_VOLATILITY_REGIMES'!$C$6,"Normal",IF(F66<'04_VOLATILITY_REGIMES'!$C$7,"High","Extreme")))) | P66: =O67 | Q66: =YEAR(A66)
A67: 41373 | B67: ='01_RAW_Spot'!B67 | C67: ='01_RAW_IV'!B67 | D67: =LN(B67/B66) | E67: =STDEV(D47:D67)*SQRT(252) | F67: =STDEV(D5:D67)*SQRT(252) | G67: =IF(OR(C67="",F67=""),"",C67-F67) | H67: =IF(OR(C67="",F67="",F67=0),"",C67/F67) | I67: =IF('01_RAW_FwdRV'!B67="","",'01_RAW_FwdRV'!B67) | J67: =IF(ROW()<=3286,STDEV(D68:D88)*SQRT(252),"") | K67: =IF(ROW()<=3244,LN(B130/B67),"") | O67: =IF(F67="","",IF(F67<'04_VOLATILITY_REGIMES'!$C$5,"Low",IF(F67<'04_VOLATILITY_REGIMES'!$C$6,"Normal",IF(F67<'04_VOLATILITY_REGIMES'!$C$7,"High","Extreme")))) | P67: =O68 | Q67: =YEAR(A67)
A68: 41374 | B68: ='01_RAW_Spot'!B68 | C68: ='01_RAW_IV'!B68 | D68: =LN(B68/B67) | E68: =STDEV(D48:D68)*SQRT(252) | F68: =STDEV(D6:D68)*SQRT(252) | G68: =IF(OR(C68="",F68=""),"",C68-F68) | H68: =IF(OR(C68="",F68="",F68=0),"",C68/F68) | I68: =IF('01_RAW_FwdRV'!B68="","",'01_RAW_FwdRV'!B68) | J68: =IF(ROW()<=3286,STDEV(D69:D89)*SQRT(252),"") | K68: =IF(ROW()<=3244,LN(B131/B68),"") | O68: =IF(F68="","",IF(F68<'04_VOLATILITY_REGIMES'!$C$5,"Low",IF(F68<'04_VOLATILITY_REGIMES'!$C$6,"Normal",IF(F68<'04_VOLATILITY_REGIMES'!$C$7,"High","Extreme")))) | P68: =O69 | Q68: =YEAR(A68)
A69: 41376 | B69: ='01_RAW_Spot'!B69 | C69: ='01_RAW_IV'!B69 | D69: =LN(B69/B68) | E69: =STDEV(D49:D69)*SQRT(252) | F69: =STDEV(D7:D69)*SQRT(252) | G69: =IF(OR(C69="",F69=""),"",C69-F69) | H69: =IF(OR(C69="",F69="",F69=0),"",C69/F69) | I69: =IF('01_RAW_FwdRV'!B69="","",'01_RAW_FwdRV'!B69) | J69: =IF(ROW()<=3286,STDEV(D70:D90)*SQRT(252),"") | K69: =IF(ROW()<=3244,LN(B132/B69),"") | O69: =IF(F69="","",IF(F69<'04_VOLATILITY_REGIMES'!$C$5,"Low",IF(F69<'04_VOLATILITY_REGIMES'!$C$6,"Normal",IF(F69<'04_VOLATILITY_REGIMES'!$C$7,"High","Extreme")))) | P69: =O70 | Q69: =YEAR(A69)
A70: 41379 | B70: ='01_RAW_Spot'!B70 | C70: ='01_RAW_IV'!B70 | D70: =LN(B70/B69) | E70: =STDEV(D50:D70)*SQRT(252) | F70: =STDEV(D8:D70)*SQRT(252) | G70: =IF(OR(C70="",F70=""),"",C70-F70) | H70: =IF(OR(C70="",F70="",F70=0),"",C70/F70) | I70: =IF('01_RAW_FwdRV'!B70="","",'01_RAW_FwdRV'!B70) | J70: =IF(ROW()<=3286,STDEV(D71:D91)*SQRT(252),"") | K70: =IF(ROW()<=3244,LN(B133/B70),"") | O70: =IF(F70="","",IF(F70<'04_VOLATILITY_REGIMES'!$C$5,"Low",IF(F70<'04_VOLATILITY_REGIMES'!$C$6,"Normal",IF(F70<'04_VOLATILITY_REGIMES'!$C$7,"High","Extreme")))) | P70: =O71 | Q70: =YEAR(A70)
A71: 41380 | B71: ='01_RAW_Spot'!B71 | C71: ='01_RAW_IV'!B71 | D71: =LN(B71/B70) | E71: =STDEV(D51:D71)*SQRT(252) | F71: =STDEV(D9:D71)*SQRT(252) | G71: =IF(OR(C71="",F71=""),"",C71-F71) | H71: =IF(OR(C71="",F71="",F71=0),"",C71/F71) | I71: =IF('01_RAW_FwdRV'!B71="","",'01_RAW_FwdRV'!B71) | J71: =IF(ROW()<=3286,STDEV(D72:D92)*SQRT(252),"") | K71: =IF(ROW()<=3244,LN(B134/B71),"") | O71: =IF(F71="","",IF(F71<'04_VOLATILITY_REGIMES'!$C$5,"Low",IF(F71<'04_VOLATILITY_REGIMES'!$C$6,"Normal",IF(F71<'04_VOLATILITY_REGIMES'!$C$7,"High","Extreme")))) | P71: =O72 | Q71: =YEAR(A71)
A72: 41381 | B72: ='01_RAW_Spot'!B72 | C72: ='01_RAW_IV'!B72 | D72: =LN(B72/B71) | E72: =STDEV(D52:D72)*SQRT(252) | F72: =STDEV(D10:D72)*SQRT(252) | G72: =IF(OR(C72="",F72=""),"",C72-F72) | H72: =IF(OR(C72="",F72="",F72=0),"",C72/F72) | I72: =IF('01_RAW_FwdRV'!B72="","",'01_RAW_FwdRV'!B72) | J72: =IF(ROW()<=3286,STDEV(D73:D93)*SQRT(252),"") | K72: =IF(ROW()<=3244,LN(B135/B72),"") | O72: =IF(F72="","",IF(F72<'04_VOLATILITY_REGIMES'!$C$5,"Low",IF(F72<'04_VOLATILITY_REGIMES'!$C$6,"Normal",IF(F72<'04_VOLATILITY_REGIMES'!$C$7,"High","Extreme")))) | P72: =O73 | Q72: =YEAR(A72)
A73: 41382 | B73: ='01_RAW_Spot'!B73 | C73: ='01_RAW_IV'!B73 | D73: =LN(B73/B72) | E73: =STDEV(D53:D73)*SQRT(252) | F73: =STDEV(D11:D73)*SQRT(252) | G73: =IF(OR(C73="",F73=""),"",C73-F73) | H73: =IF(OR(C73="",F73="",F73=0),"",C73/F73) | I73: =IF('01_RAW_FwdRV'!B73="","",'01_RAW_FwdRV'!B73) | J73: =IF(ROW()<=3286,STDEV(D74:D94)*SQRT(252),"") | K73: =IF(ROW()<=3244,LN(B136/B73),"") | O73: =IF(F73="","",IF(F73<'04_VOLATILITY_REGIMES'!$C$5,"Low",IF(F73<'04_VOLATILITY_REGIMES'!$C$6,"Normal",IF(F73<'04_VOLATILITY_REGIMES'!$C$7,"High","Extreme")))) | P73: =O74 | Q73: =YEAR(A73)
A74: 41386 | B74: ='01_RAW_Spot'!B74 | C74: ='01_RAW_IV'!B74 | D74: =LN(B74/B73) | E74: =STDEV(D54:D74)*SQRT(252) | F74: =STDEV(D12:D74)*SQRT(252) | G74: =IF(OR(C74="",F74=""),"",C74-F74) | H74: =IF(OR(C74="",F74="",F74=0),"",C74/F74) | I74: =IF('01_RAW_FwdRV'!B74="","",'01_RAW_FwdRV'!B74) | J74: =IF(ROW()<=3286,STDEV(D75:D95)*SQRT(252),"") | K74: =IF(ROW()<=3244,LN(B137/B74),"") | O74: =IF(F74="","",IF(F74<'04_VOLATILITY_REGIMES'!$C$5,"Low",IF(F74<'04_VOLATILITY_REGIMES'!$C$6,"Normal",IF(F74<'04_VOLATILITY_REGIMES'!$C$7,"High","Extreme")))) | P74: =O75 | Q74: =YEAR(A74)
A75: 41387 | B75: ='01_RAW_Spot'!B75 | C75: ='01_RAW_IV'!B75 | D75: =LN(B75/B74) | E75: =STDEV(D55:D75)*SQRT(252) | F75: =STDEV(D13:D75)*SQRT(252) | G75: =IF(OR(C75="",F75=""),"",C75-F75) | H75: =IF(OR(C75="",F75="",F75=0),"",C75/F75) | I75: =IF('01_RAW_FwdRV'!B75="","",'01_RAW_FwdRV'!B75) | J75: =IF(ROW()<=3286,STDEV(D76:D96)*SQRT(252),"") | K75: =IF(ROW()<=3244,LN(B138/B75),"") | O75: =IF(F75="","",IF(F75<'04_VOLATILITY_REGIMES'!$C$5,"Low",IF(F75<'04_VOLATILITY_REGIMES'!$C$6,"Normal",IF(F75<'04_VOLATILITY_REGIMES'!$C$7,"High","Extreme")))) | P75: =O76 | Q75: =YEAR(A75)
A76: 41389 | B76: ='01_RAW_Spot'!B76 | C76: ='01_RAW_IV'!B76 | D76: =LN(B76/B75) | E76: =STDEV(D56:D76)*SQRT(252) | F76: =STDEV(D14:D76)*SQRT(252) | G76: =IF(OR(C76="",F76=""),"",C76-F76) | H76: =IF(OR(C76="",F76="",F76=0),"",C76/F76) | I76: =IF('01_RAW_FwdRV'!B76="","",'01_RAW_FwdRV'!B76) | J76: =IF(ROW()<=3286,STDEV(D77:D97)*SQRT(252),"") | K76: =IF(ROW()<=3244,LN(B139/B76),"") | O76: =IF(F76="","",IF(F76<'04_VOLATILITY_REGIMES'!$C$5,"Low",IF(F76<'04_VOLATILITY_REGIMES'!$C$6,"Normal",IF(F76<'04_VOLATILITY_REGIMES'!$C$7,"High","Extreme")))) | P76: =O77 | Q76: =YEAR(A76)
...

Sheet 03_EXPLORATORY_ANALYSIS
A1: Descriptive Statistics — IV, Trailing RV (annualized)
A2: Full sample + calendar year. Live formulas reference 02_MASTER.
A4: Statistic | B4: IV_3M_ATM | C4: tRV_1M | D4: tRV_3M | E4: Fwd_RV_3M[OUT]
A5: Mean | B5: =AVERAGE('02_MASTER'!C2:C3307) | C5: =AVERAGE('02_MASTER'!E2:E3307) | D5: =AVERAGE('02_MASTER'!F2:F3307) | E5: =AVERAGE('02_MASTER'!I2:I3307)
A6: Median | B6: =MEDIAN('02_MASTER'!C2:C3307) | C6: =MEDIAN('02_MASTER'!E2:E3307) | D6: =MEDIAN('02_MASTER'!F2:F3307) | E6: =MEDIAN('02_MASTER'!I2:I3307)
A7: Std Dev | B7: =STDEV('02_MASTER'!C2:C3307) | C7: =STDEV('02_MASTER'!E2:E3307) | D7: =STDEV('02_MASTER'!F2:F3307) | E7: =STDEV('02_MASTER'!I2:I3307)
A8: Min | B8: =MIN('02_MASTER'!C2:C3307) | C8: =MIN('02_MASTER'!E2:E3307) | D8: =MIN('02_MASTER'!F2:F3307) | E8: =MIN('02_MASTER'!I2:I3307)
A9: P10 | B9: =PERCENTILE('02_MASTER'!C2:C3307,0.1) | C9: =PERCENTILE('02_MASTER'!E2:E3307,0.1) | D9: =PERCENTILE('02_MASTER'!F2:F3307,0.1) | E9: =PERCENTILE('02_MASTER'!I2:I3307,0.1)
A10: P25 | B10: =PERCENTILE('02_MASTER'!C2:C3307,0.25) | C10: =PERCENTILE('02_MASTER'!E2:E3307,0.25) | D10: =PERCENTILE('02_MASTER'!F2:F3307,0.25) | E10: =PERCENTILE('02_MASTER'!I2:I3307,0.25)
A11: P50 | B11: =PERCENTILE('02_MASTER'!C2:C3307,0.5) | C11: =PERCENTILE('02_MASTER'!E2:E3307,0.5) | D11: =PERCENTILE('02_MASTER'!F2:F3307,0.5) | E11: =PERCENTILE('02_MASTER'!I2:I3307,0.5)
A12: P75 | B12: =PERCENTILE('02_MASTER'!C2:C3307,0.75) | C12: =PERCENTILE('02_MASTER'!E2:E3307,0.75) | D12: =PERCENTILE('02_MASTER'!F2:F3307,0.75) | E12: =PERCENTILE('02_MASTER'!I2:I3307,0.75)
A13: P90 | B13: =PERCENTILE('02_MASTER'!C2:C3307,0.9) | C13: =PERCENTILE('02_MASTER'!E2:E3307,0.9) | D13: =PERCENTILE('02_MASTER'!F2:F3307,0.9) | E13: =PERCENTILE('02_MASTER'!I2:I3307,0.9)
A14: Max | B14: =MAX('02_MASTER'!C2:C3307) | C14: =MAX('02_MASTER'!E2:E3307) | D14: =MAX('02_MASTER'!F2:F3307) | E14: =MAX('02_MASTER'!I2:I3307)
A17: By calendar year
A18: Year | B18: IV mean | C18: IV max | D18: tRV3M mean | E18: tRV3M max | F18: IV-tRV3M mean | G18: FwdRV3M mean | H18: Spot (yr-end)
A19: 2013 | B19: =AVERAGEIFS('02_MASTER'!$C$2:$C$3307,'02_MASTER'!$Q$2:$Q$3307,A19) | C19: =_xlfn.MAXIFS('02_MASTER'!$C$2:$C$3307,'02_MASTER'!$Q$2:$Q$3307,A19) | D19: =AVERAGEIFS('02_MASTER'!$F$2:$F$3307,'02_MASTER'!$Q$2:$Q$3307,A19) | E19: =_xlfn.MAXIFS('02_MASTER'!$F$2:$F$3307,'02_MASTER'!$Q$2:$Q$3307,A19) | F19: =AVERAGEIFS('02_MASTER'!$G$2:$G$3307,'02_MASTER'!$Q$2:$Q$3307,A19) | G19: =AVERAGEIFS('02_MASTER'!$I$2:$I$3307,'02_MASTER'!$Q$2:$Q$3307,A19) | H19: =INDEX('02_MASTER'!$B$2:$B$3307,MATCH(_xlfn.MAXIFS('02_MASTER'!$A$2:$A$3307,'02_MASTER'!$Q$2:$Q$3307,A19),'02_MASTER'!$A$2:$A$3307,0))
A20: 2014 | B20: =AVERAGEIFS('02_MASTER'!$C$2:$C$3307,'02_MASTER'!$Q$2:$Q$3307,A20) | C20: =_xlfn.MAXIFS('02_MASTER'!$C$2:$C$3307,'02_MASTER'!$Q$2:$Q$3307,A20) | D20: =AVERAGEIFS('02_MASTER'!$F$2:$F$3307,'02_MASTER'!$Q$2:$Q$3307,A20) | E20: =_xlfn.MAXIFS('02_MASTER'!$F$2:$F$3307,'02_MASTER'!$Q$2:$Q$3307,A20) | F20: =AVERAGEIFS('02_MASTER'!$G$2:$G$3307,'02_MASTER'!$Q$2:$Q$3307,A20) | G20: =AVERAGEIFS('02_MASTER'!$I$2:$I$3307,'02_MASTER'!$Q$2:$Q$3307,A20) | H20: =INDEX('02_MASTER'!$B$2:$B$3307,MATCH(_xlfn.MAXIFS('02_MASTER'!$A$2:$A$3307,'02_MASTER'!$Q$2:$Q$3307,A20),'02_MASTER'!$A$2:$A$3307,0))
A21: 2015 | B21: =AVERAGEIFS('02_MASTER'!$C$2:$C$3307,'02_MASTER'!$Q$2:$Q$3307,A21) | C21: =_xlfn.MAXIFS('02_MASTER'!$C$2:$C$3307,'02_MASTER'!$Q$2:$Q$3307,A21) | D21: =AVERAGEIFS('02_MASTER'!$F$2:$F$3307,'02_MASTER'!$Q$2:$Q$3307,A21) | E21: =_xlfn.MAXIFS('02_MASTER'!$F$2:$F$3307,'02_MASTER'!$Q$2:$Q$3307,A21) | F21: =AVERAGEIFS('02_MASTER'!$G$2:$G$3307,'02_MASTER'!$Q$2:$Q$3307,A21) | G21: =AVERAGEIFS('02_MASTER'!$I$2:$I$3307,'02_MASTER'!$Q$2:$Q$3307,A21) | H21: =INDEX('02_MASTER'!$B$2:$B$3307,MATCH(_xlfn.MAXIFS('02_MASTER'!$A$2:$A$3307,'02_MASTER'!$Q$2:$Q$3307,A21),'02_MASTER'!$A$2:$A$3307,0))
A22: 2016 | B22: =AVERAGEIFS('02_MASTER'!$C$2:$C$3307,'02_MASTER'!$Q$2:$Q$3307,A22) | C22: =_xlfn.MAXIFS('02_MASTER'!$C$2:$C$3307,'02_MASTER'!$Q$2:$Q$3307,A22) | D22: =AVERAGEIFS('02_MASTER'!$F$2:$F$3307,'02_MASTER'!$Q$2:$Q$3307,A22) | E22: =_xlfn.MAXIFS('02_MASTER'!$F$2:$F$3307,'02_MASTER'!$Q$2:$Q$3307,A22) | F22: =AVERAGEIFS('02_MASTER'!$G$2:$G$3307,'02_MASTER'!$Q$2:$Q$3307,A22) | G22: =AVERAGEIFS('02_MASTER'!$I$2:$I$3307,'02_MASTER'!$Q$2:$Q$3307,A22) | H22: =INDEX('02_MASTER'!$B$2:$B$3307,MATCH(_xlfn.MAXIFS('02_MASTER'!$A$2:$A$3307,'02_MASTER'!$Q$2:$Q$3307,A22),'02_MASTER'!$A$2:$A$3307,0))
A23: 2017 | B23: =AVERAGEIFS('02_MASTER'!$C$2:$C$3307,'02_MASTER'!$Q$2:$Q$3307,A23) | C23: =_xlfn.MAXIFS('02_MASTER'!$C$2:$C$3307,'02_MASTER'!$Q$2:$Q$3307,A23) | D23: =AVERAGEIFS('02_MASTER'!$F$2:$F$3307,'02_MASTER'!$Q$2:$Q$3307,A23) | E23: =_xlfn.MAXIFS('02_MASTER'!$F$2:$F$3307,'02_MASTER'!$Q$2:$Q$3307,A23) | F23: =AVERAGEIFS('02_MASTER'!$G$2:$G$3307,'02_MASTER'!$Q$2:$Q$3307,A23) | G23: =AVERAGEIFS('02_MASTER'!$I$2:$I$3307,'02_MASTER'!$Q$2:$Q$3307,A23) | H23: =INDEX('02_MASTER'!$B$2:$B$3307,MATCH(_xlfn.MAXIFS('02_MASTER'!$A$2:$A$3307,'02_MASTER'!$Q$2:$Q$3307,A23),'02_MASTER'!$A$2:$A$3307,0))
A24: 2018 | B24: =AVERAGEIFS('02_MASTER'!$C$2:$C$3307,'02_MASTER'!$Q$2:$Q$3307,A24) | C24: =_xlfn.MAXIFS('02_MASTER'!$C$2:$C$3307,'02_MASTER'!$Q$2:$Q$3307,A24) | D24: =AVERAGEIFS('02_MASTER'!$F$2:$F$3307,'02_MASTER'!$Q$2:$Q$3307,A24) | E24: =_xlfn.MAXIFS('02_MASTER'!$F$2:$F$3307,'02_MASTER'!$Q$2:$Q$3307,A24) | F24: =AVERAGEIFS('02_MASTER'!$G$2:$G$3307,'02_MASTER'!$Q$2:$Q$3307,A24) | G24: =AVERAGEIFS('02_MASTER'!$I$2:$I$3307,'02_MASTER'!$Q$2:$Q$3307,A24) | H24: =INDEX('02_MASTER'!$B$2:$B$3307,MATCH(_xlfn.MAXIFS('02_MASTER'!$A$2:$A$3307,'02_MASTER'!$Q$2:$Q$3307,A24),'02_MASTER'!$A$2:$A$3307,0))
A25: 2019 | B25: =AVERAGEIFS('02_MASTER'!$C$2:$C$3307,'02_MASTER'!$Q$2:$Q$3307,A25) | C25: =_xlfn.MAXIFS('02_MASTER'!$C$2:$C$3307,'02_MASTER'!$Q$2:$Q$3307,A25) | D25: =AVERAGEIFS('02_MASTER'!$F$2:$F$3307,'02_MASTER'!$Q$2:$Q$3307,A25) | E25: =_xlfn.MAXIFS('02_MASTER'!$F$2:$F$3307,'02_MASTER'!$Q$2:$Q$3307,A25) | F25: =AVERAGEIFS('02_MASTER'!$G$2:$G$3307,'02_MASTER'!$Q$2:$Q$3307,A25) | G25: =AVERAGEIFS('02_MASTER'!$I$2:$I$3307,'02_MASTER'!$Q$2:$Q$3307,A25) | H25: =INDEX('02_MASTER'!$B$2:$B$3307,MATCH(_xlfn.MAXIFS('02_MASTER'!$A$2:$A$3307,'02_MASTER'!$Q$2:$Q$3307,A25),'02_MASTER'!$A$2:$A$3307,0))
A26: 2020 | B26: =AVERAGEIFS('02_MASTER'!$C$2:$C$3307,'02_MASTER'!$Q$2:$Q$3307,A26) | C26: =_xlfn.MAXIFS('02_MASTER'!$C$2:$C$3307,'02_MASTER'!$Q$2:$Q$3307,A26) | D26: =AVERAGEIFS('02_MASTER'!$F$2:$F$3307,'02_MASTER'!$Q$2:$Q$3307,A26) | E26: =_xlfn.MAXIFS('02_MASTER'!$F$2:$F$3307,'02_MASTER'!$Q$2:$Q$3307,A26) | F26: =AVERAGEIFS('02_MASTER'!$G$2:$G$3307,'02_MASTER'!$Q$2:$Q$3307,A26) | G26: =AVERAGEIFS('02_MASTER'!$I$2:$I$3307,'02_MASTER'!$Q$2:$Q$3307,A26) | H26: =INDEX('02_MASTER'!$B$2:$B$3307,MATCH(_xlfn.MAXIFS('02_MASTER'!$A$2:$A$3307,'02_MASTER'!$Q$2:$Q$3307,A26),'02_MASTER'!$A$2:$A$3307,0))
A27: 2021 | B27: =AVERAGEIFS('02_MASTER'!$C$2:$C$3307,'02_MASTER'!$Q$2:$Q$3307,A27) | C27: =_xlfn.MAXIFS('02_MASTER'!$C$2:$C$3307,'02_MASTER'!$Q$2:$Q$3307,A27) | D27: =AVERAGEIFS('02_MASTER'!$F$2:$F$3307,'02_MASTER'!$Q$2:$Q$3307,A27) | E27: =_xlfn.MAXIFS('02_MASTER'!$F$2:$F$3307,'02_MASTER'!$Q$2:$Q$3307,A27) | F27: =AVERAGEIFS('02_MASTER'!$G$2:$G$3307,'02_MASTER'!$Q$2:$Q$3307,A27) | G27: =AVERAGEIFS('02_MASTER'!$I$2:$I$3307,'02_MASTER'!$Q$2:$Q$3307,A27) | H27: =INDEX('02_MASTER'!$B$2:$B$3307,MATCH(_xlfn.MAXIFS('02_MASTER'!$A$2:$A$3307,'02_MASTER'!$Q$2:$Q$3307,A27),'02_MASTER'!$A$2:$A$3307,0))
A28: 2022 | B28: =AVERAGEIFS('02_MASTER'!$C$2:$C$3307,'02_MASTER'!$Q$2:$Q$3307,A28) | C28: =_xlfn.MAXIFS('02_MASTER'!$C$2:$C$3307,'02_MASTER'!$Q$2:$Q$3307,A28) | D28: =AVERAGEIFS('02_MASTER'!$F$2:$F$3307,'02_MASTER'!$Q$2:$Q$3307,A28) | E28: =_xlfn.MAXIFS('02_MASTER'!$F$2:$F$3307,'02_MASTER'!$Q$2:$Q$3307,A28) | F28: =AVERAGEIFS('02_MASTER'!$G$2:$G$3307,'02_MASTER'!$Q$2:$Q$3307,A28) | G28: =AVERAGEIFS('02_MASTER'!$I$2:$I$3307,'02_MASTER'!$Q$2:$Q$3307,A28) | H28: =INDEX('02_MASTER'!$B$2:$B$3307,MATCH(_xlfn.MAXIFS('02_MASTER'!$A$2:$A$3307,'02_MASTER'!$Q$2:$Q$3307,A28),'02_MASTER'!$A$2:$A$3307,0))
A29: 2023 | B29: =AVERAGEIFS('02_MASTER'!$C$2:$C$3307,'02_MASTER'!$Q$2:$Q$3307,A29) | C29: =_xlfn.MAXIFS('02_MASTER'!$C$2:$C$3307,'02_MASTER'!$Q$2:$Q$3307,A29) | D29: =AVERAGEIFS('02_MASTER'!$F$2:$F$3307,'02_MASTER'!$Q$2:$Q$3307,A29) | E29: =_xlfn.MAXIFS('02_MASTER'!$F$2:$F$3307,'02_MASTER'!$Q$2:$Q$3307,A29) | F29: =AVERAGEIFS('02_MASTER'!$G$2:$G$3307,'02_MASTER'!$Q$2:$Q$3307,A29) | G29: =AVERAGEIFS('02_MASTER'!$I$2:$I$3307,'02_MASTER'!$Q$2:$Q$3307,A29) | H29: =INDEX('02_MASTER'!$B$2:$B$3307,MATCH(_xlfn.MAXIFS('02_MASTER'!$A$2:$A$3307,'02_MASTER'!$Q$2:$Q$3307,A29),'02_MASTER'!$A$2:$A$3307,0))
A30: 2024 | B30: =AVERAGEIFS('02_MASTER'!$C$2:$C$3307,'02_MASTER'!$Q$2:$Q$3307,A30) | C30: =_xlfn.MAXIFS('02_MASTER'!$C$2:$C$3307,'02_MASTER'!$Q$2:$Q$3307,A30) | D30: =AVERAGEIFS('02_MASTER'!$F$2:$F$3307,'02_MASTER'!$Q$2:$Q$3307,A30) | E30: =_xlfn.MAXIFS('02_MASTER'!$F$2:$F$3307,'02_MASTER'!$Q$2:$Q$3307,A30) | F30: =AVERAGEIFS('02_MASTER'!$G$2:$G$3307,'02_MASTER'!$Q$2:$Q$3307,A30) | G30: =AVERAGEIFS('02_MASTER'!$I$2:$I$3307,'02_MASTER'!$Q$2:$Q$3307,A30) | H30: =INDEX('02_MASTER'!$B$2:$B$3307,MATCH(_xlfn.MAXIFS('02_MASTER'!$A$2:$A$3307,'02_MASTER'!$Q$2:$Q$3307,A30),'02_MASTER'!$A$2:$A$3307,0))
... A32: 2026 | B32: =AVERAGEIFS('02_MASTER'!$C$2:$C$3307,'02_MASTER'!$Q$2:$Q$3307,A32) | C32: =_xlfn.MAXIFS('02_MASTER'!$C$2:$C$3307,'02_MASTER'!$Q$2:$Q$3307,A32) | D32: =AVERAGEIFS('02_MASTER'!$F$2:$F$3307,'02_MASTER'!$Q$2:$Q$3307,A32) | E32: =_xlfn.MAXIFS('02_MASTER'!$F$2:$F$3307,'02_MASTER'!$Q$2:$Q$3307,A32) | F32: =AVERAGEIFS('02_MASTER'!$G$2:$G$3307,'02_MASTER'!$Q$2:$Q$3307,A32) | G32: =AVERAGEIFS('02_MASTER'!$I$2:$I$3307,'02_MASTER'!$Q$2:$Q$3307,A32) | H32: =INDEX('02_MASTER'!$B$2:$B$3307,MATCH(_xlfn.MAXIFS('02_MASTER'!$A$2:$A$3307,'02_MASTER'!$Q$2:$Q$3307,A32),'02_MASTER'!$A$2:$A$3307,0))

Sheet 04_VOLATILITY_REGIMES
A1: Volatility Regime Map
A2: Regimes defined on trailing 3M RV, full-sample percentile bands (DESCRIPTIVE).
A4: Thresholds (trailing 3M RV)
B5: 25th pct (Low/Normal cut) | C5: =PERCENTILE('02_MASTER'!F2:F3307,0.25)
B6: 75th pct (Normal/High cut) | C6: =PERCENTILE('02_MASTER'!F2:F3307,0.75)
B7: 90th pct (High/Extreme cut) | C7: =PERCENTILE('02_MASTER'!F2:F3307,0.90)
A9: Regime | B9: Days (COUNTIF) | C9: Share | D9: Episodes | E9: Mean dur (d) | F9: Median dur | G9: Max dur
A10: Low | B10: =COUNTIF('02_MASTER'!O2:O3307,"Low") | C10: =B10/SUM($B$10:$B$13) | D10: 19 | E10: 42.7 | F10: 18 | G10: 453
A11: Normal | B11: =COUNTIF('02_MASTER'!O2:O3307,"Normal") | C11: =B11/SUM($B$10:$B$13) | D11: 48 | E11: 33.8 | F11: 18.5 | G11: 200
A12: High | B12: =COUNTIF('02_MASTER'!O2:O3307,"High") | C12: =B12/SUM($B$10:$B$13) | D12: 39 | E12: 12.5 | F12: 6 | G12: 58
A13: Extreme | B13: =COUNTIF('02_MASTER'!O2:O3307,"Extreme") | C13: =B13/SUM($B$10:$B$13) | D13: 11 | E13: 29.5 | F13: 5 | G13: 149
A15: Daily regime transition matrix (row = from, col = to; share of days)
A16: from \ to | B16: Low | C16: Normal | D16: High | E16: Extreme
A17: Low | B17: =IFERROR(COUNTIFS('02_MASTER'!$O$2:$O$3307,"Low",'02_MASTER'!$P$2:$P$3307,"Low")/COUNTIF('02_MASTER'!$O$2:$O$3307,"Low"),0) | C17: =IFERROR(COUNTIFS('02_MASTER'!$O$2:$O$3307,"Low",'02_MASTER'!$P$2:$P$3307,"Normal")/COUNTIF('02_MASTER'!$O$2:$O$3307,"Low"),0) | D17: =IFERROR(COUNTIFS('02_MASTER'!$O$2:$O$3307,"Low",'02_MASTER'!$P$2:$P$3307,"High")/COUNTIF('02_MASTER'!$O$2:$O$3307,"Low"),0) | E17: =IFERROR(COUNTIFS('02_MASTER'!$O$2:$O$3307,"Low",'02_MASTER'!$P$2:$P$3307,"Extreme")/COUNTIF('02_MASTER'!$O$2:$O$3307,"Low"),0)
A18: Normal | B18: =IFERROR(COUNTIFS('02_MASTER'!$O$2:$O$3307,"Normal",'02_MASTER'!$P$2:$P$3307,"Low")/COUNTIF('02_MASTER'!$O$2:$O$3307,"Normal"),0) | C18: =IFERROR(COUNTIFS('02_MASTER'!$O$2:$O$3307,"Normal",'02_MASTER'!$P$2:$P$3307,"Normal")/COUNTIF('02_MASTER'!$O$2:$O$3307,"Normal"),0) | D18: =IFERROR(COUNTIFS('02_MASTER'!$O$2:$O$3307,"Normal",'02_MASTER'!$P$2:$P$3307,"High")/COUNTIF('02_MASTER'!$O$2:$O$3307,"Normal"),0) | E18: =IFERROR(COUNTIFS('02_MASTER'!$O$2:$O$3307,"Normal",'02_MASTER'!$P$2:$P$3307,"Extreme")/COUNTIF('02_MASTER'!$O$2:$O$3307,"Normal"),0)
A19: High | B19: =IFERROR(COUNTIFS('02_MASTER'!$O$2:$O$3307,"High",'02_MASTER'!$P$2:$P$3307,"Low")/COUNTIF('02_MASTER'!$O$2:$O$3307,"High"),0) | C19: =IFERROR(COUNTIFS('02_MASTER'!$O$2:$O$3307,"High",'02_MASTER'!$P$2:$P$3307,"Normal")/COUNTIF('02_MASTER'!$O$2:$O$3307,"High"),0) | D19: =IFERROR(COUNTIFS('02_MASTER'!$O$2:$O$3307,"High",'02_MASTER'!$P$2:$P$3307,"High")/COUNTIF('02_MASTER'!$O$2:$O$3307,"High"),0) | E19: =IFERROR(COUNTIFS('02_MASTER'!$O$2:$O$3307,"High",'02_MASTER'!$P$2:$P$3307,"Extreme")/COUNTIF('02_MASTER'!$O$2:$O$3307,"High"),0)
A20: Extreme | B20: =IFERROR(COUNTIFS('02_MASTER'!$O$2:$O$3307,"Extreme",'02_MASTER'!$P$2:$P$3307,"Low")/COUNTIF('02_MASTER'!$O$2:$O$3307,"Extreme"),0) | C20: =IFERROR(COUNTIFS('02_MASTER'!$O$2:$O$3307,"Extreme",'02_MASTER'!$P$2:$P$3307,"Normal")/COUNTIF('02_MASTER'!$O$2:$O$3307,"Extreme"),0) | D20: =IFERROR(COUNTIFS('02_MASTER'!$O$2:$O$3307,"Extreme",'02_MASTER'!$P$2:$P$3307,"High")/COUNTIF('02_MASTER'!$O$2:$O$3307,"Extreme"),0) | E20: =IFERROR(COUNTIFS('02_MASTER'!$O$2:$O$3307,"Extreme",'02_MASTER'!$P$2:$P$3307,"Extreme")/COUNTIF('02_MASTER'!$O$2:$O$3307,"Extreme"),0)
A23: Note: episode durations computed in Python from the Regime column (run-lengths); all other cells are live formulas.

Sheet 05_IV_RV_ANALYSIS
A1: IV vs RV Analysis
A2: Spread & ratio distribution; conditional forward RV; forecast evaluation; lead/lag.
A4: IV - trailing RV_3M (vol risk premium, known at t)
A5: Statistic | B5: IV - tRV3M | C5: IV / tRV3M
A6: Mean | B6: =AVERAGE('02_MASTER'!G2:G3307) | C6: =AVERAGE('02_MASTER'!H2:H3307)
A7: Median | B7: =MEDIAN('02_MASTER'!G2:G3307) | C7: =MEDIAN('02_MASTER'!H2:H3307)
A8: Std Dev | B8: =STDEV('02_MASTER'!G2:G3307) | C8: =STDEV('02_MASTER'!H2:H3307)
A9: P10 | B9: =PERCENTILE('02_MASTER'!G2:G3307,0.1) | C9: =PERCENTILE('02_MASTER'!H2:H3307,0.1)
A10: P90 | B10: =PERCENTILE('02_MASTER'!G2:G3307,0.9) | C10: =PERCENTILE('02_MASTER'!H2:H3307,0.9)
A11: Min | B11: =MIN('02_MASTER'!G2:G3307) | C11: =MIN('02_MASTER'!H2:H3307)
A12: Max | B12: =MAX('02_MASTER'!G2:G3307) | C12: =MAX('02_MASTER'!H2:H3307)
A14: Persistence (AR1 slope) & half-life
A15: Series | B15: AR(1) phi | C15: Half-life (days)
A16: IV | B16: =SLOPE('02_MASTER'!C3:C3307,'02_MASTER'!C2:C3306) | C16: =IFERROR(LN(0.5)/LN(B16),"")
A17: tRV_3M | B17: =SLOPE('02_MASTER'!F66:F3307,'02_MASTER'!F65:F3306) | C17: =IFERROR(LN(0.5)/LN(B17),"")
A18: IV - tRV3M | B18: =SLOPE('02_MASTER'!G66:G3307,'02_MASTER'!G65:G3306) | C18: =IFERROR(LN(0.5)/LN(B18),"")
A21: Forward 3M RV by quintile of (IV - trailing RV_3M)
A22: Quintile | B22: Signal lo | C22: Signal hi | D22: n | E22: FwdRV3M mean | F22: tRV3M mean
A23: Q1 IV cheap | B23: =PERCENTILE('02_MASTER'!$G$2:$G$3307,0) | C23: =PERCENTILE('02_MASTER'!$G$2:$G$3307,0.2) | D23: =COUNTIFS('02_MASTER'!$G$2:$G$3307,">="&B23,'02_MASTER'!$G$2:$G$3307,"<="&C23) | E23: =AVERAGEIFS('02_MASTER'!$I$2:$I$3307,'02_MASTER'!$G$2:$G$3307,">="&B23,'02_MASTER'!$G$2:$G$3307,"<="&C23) | F23: =AVERAGEIFS('02_MASTER'!$F$2:$F$3307,'02_MASTER'!$G$2:$G$3307,">="&B23,'02_MASTER'!$G$2:$G$3307,"<="&C23)
A24: Q2 | B24: =PERCENTILE('02_MASTER'!$G$2:$G$3307,0.2) | C24: =PERCENTILE('02_MASTER'!$G$2:$G$3307,0.4) | D24: =COUNTIFS('02_MASTER'!$G$2:$G$3307,">"&B24,'02_MASTER'!$G$2:$G$3307,"<="&C24) | E24: =AVERAGEIFS('02_MASTER'!$I$2:$I$3307,'02_MASTER'!$G$2:$G$3307,">"&B24,'02_MASTER'!$G$2:$G$3307,"<="&C24) | F24: =AVERAGEIFS('02_MASTER'!$F$2:$F$3307,'02_MASTER'!$G$2:$G$3307,">"&B24,'02_MASTER'!$G$2:$G$3307,"<="&C24)
A25: Q3 | B25: =PERCENTILE('02_MASTER'!$G$2:$G$3307,0.4) | C25: =PERCENTILE('02_MASTER'!$G$2:$G$3307,0.6) | D25: =COUNTIFS('02_MASTER'!$G$2:$G$3307,">"&B25,'02_MASTER'!$G$2:$G$3307,"<="&C25) | E25: =AVERAGEIFS('02_MASTER'!$I$2:$I$3307,'02_MASTER'!$G$2:$G$3307,">"&B25,'02_MASTER'!$G$2:$G$3307,"<="&C25) | F25: =AVERAGEIFS('02_MASTER'!$F$2:$F$3307,'02_MASTER'!$G$2:$G$3307,">"&B25,'02_MASTER'!$G$2:$G$3307,"<="&C25)
A26: Q4 | B26: =PERCENTILE('02_MASTER'!$G$2:$G$3307,0.6) | C26: =PERCENTILE('02_MASTER'!$G$2:$G$3307,0.8) | D26: =COUNTIFS('02_MASTER'!$G$2:$G$3307,">"&B26,'02_MASTER'!$G$2:$G$3307,"<="&C26) | E26: =AVERAGEIFS('02_MASTER'!$I$2:$I$3307,'02_MASTER'!$G$2:$G$3307,">"&B26,'02_MASTER'!$G$2:$G$3307,"<="&C26) | F26: =AVERAGEIFS('02_MASTER'!$F$2:$F$3307,'02_MASTER'!$G$2:$G$3307,">"&B26,'02_MASTER'!$G$2:$G$3307,"<="&C26)
A27: Q5 IV rich | B27: =PERCENTILE('02_MASTER'!$G$2:$G$3307,0.8) | C27: =PERCENTILE('02_MASTER'!$G$2:$G$3307,1.0) | D27: =COUNTIFS('02_MASTER'!$G$2:$G$3307,">"&B27,'02_MASTER'!$G$2:$G$3307,"<="&C27) | E27: =AVERAGEIFS('02_MASTER'!$I$2:$I$3307,'02_MASTER'!$G$2:$G$3307,">"&B27,'02_MASTER'!$G$2:$G$3307,"<="&C27) | F27: =AVERAGEIFS('02_MASTER'!$F$2:$F$3307,'02_MASTER'!$G$2:$G$3307,">"&B27,'02_MASTER'!$G$2:$G$3307,"<="&C27)
A29: WARNING: signal contains tRV3M and outcome is measured vs tRV3M -> apparent monotonicity is largely RV mean-reversion, NOT IV forecasting skill.
A31: Forecast evaluation: predicting Fwd 3M RV (overlapping -> indicative)
A32: Predictor | B32: Corr with FwdRV3M | C32: Bias (fwd-pred) | D32: MAE | E32: RMSE
A33: IV (3M ATM) | B33: =CORREL('02_MASTER'!$C$65:$C$3243,'02_MASTER'!$I$65:$I$3243) | C33: =AVERAGE('02_MASTER'!$I$65:$I$3243)-AVERAGE('02_MASTER'!$C$65:$C$3243) | D33: =SUMPRODUCT(ABS('02_MASTER'!$I$65:$I$3243-'02_MASTER'!$C$65:$C$3243))/COUNT('02_MASTER'!$I$65:$I$3243) | E33: =SQRT(SUMPRODUCT(('02_MASTER'!$I$65:$I$3243-'02_MASTER'!$C$65:$C$3243)^2)/COUNT('02_MASTER'!$I$65:$I$3243))
A34: Trailing RV_3M (naive) | B34: =CORREL('02_MASTER'!$F$65:$F$3243,'02_MASTER'!$I$65:$I$3243) | C34: =AVERAGE('02_MASTER'!$I$65:$I$3243)-AVERAGE('02_MASTER'!$F$65:$F$3243) | D34: =SUMPRODUCT(ABS('02_MASTER'!$I$65:$I$3243-'02_MASTER'!$F$65:$F$3243))/COUNT('02_MASTER'!$I$65:$I$3243) | E34: =SQRT(SUMPRODUCT(('02_MASTER'!$I$65:$I$3243-'02_MASTER'!$F$65:$F$3243)^2)/COUNT('02_MASTER'!$I$65:$I$3243))
A36: Clean overlap window rows 65:3243 (both trailing RV & forward RV populated). n=3179. Overlapping 3M windows -> significance indicative.
A38: Lead/Lag: corr( IV_t , tRV3M_{t+k} )
A39: k (days) | B39: Interpretation | C39: Correlation
A40: -63 | B40: RV leads IV | C40: =CORREL('02_MASTER'!$C$128:$C$3307,'02_MASTER'!$F$65:$F$3244)
A41: -21 | B41: RV leads IV | C41: =CORREL('02_MASTER'!$C$86:$C$3307,'02_MASTER'!$F$65:$F$3286)
A42: -5 | B42: RV leads IV | C42: =CORREL('02_MASTER'!$C$70:$C$3307,'02_MASTER'!$F$65:$F$3302)
A43: 0 | B43: contemporaneous | C43: =CORREL('02_MASTER'!$C$65:$C$3307,'02_MASTER'!$F$65:$F$3307)
A44: 5 | B44: IV leads RV | C44: =CORREL('02_MASTER'!$C$65:$C$3302,'02_MASTER'!$F$70:$F$3307)
A45: 21 | B45: IV leads RV | C45: =CORREL('02_MASTER'!$C$65:$C$3286,'02_MASTER'!$F$86:$F$3307)
A46: 63 | B46: IV leads RV | C46: =CORREL('02_MASTER'!$C$65:$C$3244,'02_MASTER'!$F$128:$F$3307)

Sheet 06_EXTREME_EVENTS
A1: Extreme / Notable Event Map
A2: Peak-IV day per calendar year. Quantitative only — no hindsight narrative. Fwd fields are OUTCOMES.
A4: Date | B4: Spot | C4: IV | D4: tRV3M | E4: IV-RV | F4: IV pct | G4: RV pct | H4: Fwd 1M spot | I4: Fwd 3M spot | J4: Fwd 1M RV | K4: Fwd 3M RV
A5: 41515 | B5: 66.595 | C5: 0.1577 | D5: 0.1754 | E5: -0.0177 | F5: 1 | G5: 0.981 | H5: -0.0616 | I5: -0.0656 | J5: 0.186 | K5: 0.1311
A6: 41736 | B6: 60.125 | C6: 0.1174 | D6: 0.0643 | E6: 0.0531 | F6: 0.991 | G6: 0.829 | H6: -0.0076 | I6: -0.0032 | J6: 0.0504 | K6: 0.0556
A7: 42131 | B7: 64.24 | C7: 0.08 | D7: 0.0552 | E7: 0.0248 | F7: 0.871 | G7: 0.625 | H7: -0.0076 | I7: -0.0076 | J7: 0.0498 | K7: 0.0411
A8: 42545 | B8: 67.9688 | C8: 0.0702 | D8: 0.0439 | E8: 0.0264 | F8: 0.799 | G8: 0.393 | H8: -0.0103 | I8: -0.0224 | J8: 0.0333 | K8: 0.0335
A9: 42746 | B9: 68.33 | C9: 0.0582 | D9: 0.0477 | E9: 0.0105 | F9: 0.593 | G9: 0.487 | H9: -0.0214 | I9: -0.0565 | J9: 0.0337 | K9: 0.0414
A10: 43461 | B10: 70.3525 | C10: 0.0824 | D10: 0.0872 | E10: -0.0048 | F10: 0.879 | G10: 0.953 | H10: 0.0116 | I10: -0.0173 | J10: 0.0681 | K10: 0.0598
A11: 43517 | B11: 71.2487 | C11: 0.0883 | D11: 0.0806 | E11: 0.0077 | F11: 0.906 | G11: 0.939 | H11: -0.0341 | I11: -0.0195 | J11: 0.0554 | K11: 0.0671
A12: 43920 | B12: 75.4163 | C12: 0.0896 | D12: 0.0665 | E12: 0.0231 | F12: 0.911 | G12: 0.86 | H12: 0.0046 | I12: -0.0064 | J12: 0.0834 | K12: 0.0567
A13: 44298 | B13: 75.055 | C13: 0.0653 | D13: 0.0584 | E13: 0.0069 | F13: 0.75 | G13: 0.706 | H13: -0.0248 | I13: -0.0068 | J13: 0.0459 | K13: 0.0461
A14: 44628 | B14: 76.9125 | C14: 0.0714 | D14: 0.0578 | E14: 0.0136 | F14: 0.807 | G14: 0.694 | H14: -0.0132 | I14: 0.0145 | J14: 0.0489 | K14: 0.0423
A15: 45001 | B15: 82.7363 | C15: 0.0544 | D15: 0.0456 | E15: 0.0088 | F15: 0.497 | G15: 0.43 | H15: -0.0078 | I15: -0.0095 | J15: 0.0339 | K15: 0.0298
A16: 45653 | B16: 85.54 | C16: 0.0359 | D16: 0.0129 | E16: 0.023 | F16: 0.11 | G16: 0.026 | H16: 0.0093 | I16: -0.0003 | J16: 0.0342 | K16: 0.0412
... A18: 46114 | B18: 93.105 | C18: 0.0719 | D18: 0.0691 | E18: 0.0028 | F18: 0.814 | G18: 0.876 | H18: 0.0161 | I18: 0.0198 | J18: 0.0501 | K18: 0.0607
A20: Observation: the largest daily USDINR moves and the single IV peak (Aug-2013) cluster in the 2013 taper era; later years peak at progressively lower IV (regime compression).

Sheet 07_CANDIDATE_PATTERNS
A1: Candidate Pattern Library
A2: Precisely defined, quantified, UNRANKED. Significance indicative (overlapping windows). NOT strategies.
A4: ID | B4: Definition | C4: n | D4: Cond. mean | E4: Base mean | F4: Diff | G4: Horizon | H4: Note
A5: P1 | B5: IV > 90th pct (full-sample) -> Fwd 3M RV | C5: =COUNTIFS('02_MASTER'!$C$2:$C$3307,">"&PERCENTILE('02_MASTER'!$C$2:$C$3307,0.9)) | D5: =AVERAGEIFS('02_MASTER'!$I$2:$I$3307,'02_MASTER'!$C$2:$C$3307,">"&PERCENTILE('02_MASTER'!$C$2:$C$3307,0.9)) | E5: =AVERAGE('02_MASTER'!$I$2:$I$3307) | F5: =D5-E5 | G5: 3M | H5: High IV -> high fwd RV; concentrated 2013; very noisy
A6: P2 | B6: IV < 10th pct -> Fwd 3M RV | C6: =COUNTIFS('02_MASTER'!$C$2:$C$3307,"<"&PERCENTILE('02_MASTER'!$C$2:$C$3307,0.1)) | D6: =AVERAGEIFS('02_MASTER'!$I$2:$I$3307,'02_MASTER'!$C$2:$C$3307,"<"&PERCENTILE('02_MASTER'!$C$2:$C$3307,0.1)) | E6: =AVERAGE('02_MASTER'!$I$2:$I$3307) | F6: =D6-E6 | G6: 3M | H6: Low IV -> low fwd RV; concentrated 2023-24 calm
A7: P3 | B7: tRV3M > 90th pct -> Fwd 3M RV | C7: =COUNTIFS('02_MASTER'!$F$2:$F$3307,">"&PERCENTILE('02_MASTER'!$F$2:$F$3307,0.9)) | D7: =AVERAGEIFS('02_MASTER'!$I$2:$I$3307,'02_MASTER'!$F$2:$F$3307,">"&PERCENTILE('02_MASTER'!$F$2:$F$3307,0.9)) | E7: =AVERAGE('02_MASTER'!$I$2:$I$3307) | F7: =D7-E7 | G7: 3M | H7: Realized persistence; not IV skill
A8: P4 | B8: (IV-tRV3M) > 90th pct -> Fwd 3M RV | C8: =COUNTIFS('02_MASTER'!$G$2:$G$3307,">"&PERCENTILE('02_MASTER'!$G$2:$G$3307,0.9)) | D8: =AVERAGEIFS('02_MASTER'!$I$2:$I$3307,'02_MASTER'!$G$2:$G$3307,">"&PERCENTILE('02_MASTER'!$G$2:$G$3307,0.9)) | E8: =AVERAGE('02_MASTER'!$I$2:$I$3307) | F8: =D8-E8 | G8: 3M | H8: VRP rich; weak effect on fwd RV level
A9: P5 | B9: (IV-tRV3M) < 10th pct -> Fwd 3M RV | C9: =COUNTIFS('02_MASTER'!$G$2:$G$3307,"<"&PERCENTILE('02_MASTER'!$G$2:$G$3307,0.1)) | D9: =AVERAGEIFS('02_MASTER'!$I$2:$I$3307,'02_MASTER'!$G$2:$G$3307,"<"&PERCENTILE('02_MASTER'!$G$2:$G$3307,0.1)) | E9: =AVERAGE('02_MASTER'!$I$2:$I$3307) | F9: =D9-E9 | G9: 3M | H9: VRP cheap; weak effect
A10: P6 | B10: IV > 90th pct -> Fwd 3M spot move | C10: =COUNTIFS('02_MASTER'!$C$2:$C$3307,">"&PERCENTILE('02_MASTER'!$C$2:$C$3307,0.9)) | D10: =AVERAGEIFS('02_MASTER'!$K$2:$K$3307,'02_MASTER'!$C$2:$C$3307,">"&PERCENTILE('02_MASTER'!$C$2:$C$3307,0.9)) | E10: =AVERAGE('02_MASTER'!$K$2:$K$3307) | F10: =D10-E10 | G10: 3M | H10: NULL: IV level does not signal direction
A11: P7 | B11: Low-vol regime (tRV3M<25th) -> Fwd 3M RV | C11: =COUNTIFS('02_MASTER'!$F$2:$F$3307,"<"&PERCENTILE('02_MASTER'!$F$2:$F$3307,0.25)) | D11: =AVERAGEIFS('02_MASTER'!$I$2:$I$3307,'02_MASTER'!$F$2:$F$3307,"<"&PERCENTILE('02_MASTER'!$F$2:$F$3307,0.25)) | E11: =AVERAGE('02_MASTER'!$I$2:$I$3307) | F11: =D11-E11 | G11: 3M | H11: Calm persists (mean-reversion of calm)
A14: Convention: percentile thresholds are full-sample (descriptive). For any backtest, re-derive with expanding/rolling windows to avoid look-ahead. Diff is NOT a P&L.

Sheet 08_CHARTS
A1: Visual Research Output
